[2024-02-24 10:57:30,074:INFO:main:welcome to my custom log]
[2024-02-24 10:57:52,562:INFO:main:welcome to my custom log]
[2024-02-24 22:24:21,648:INFO:common:yaml file: config\config.yaml loaded successfully]
[2024-02-24 22:26:04,510:INFO:common:yaml file: config\config.yaml loaded successfully]
[2024-02-24 22:29:50,431:INFO:common:yaml file: config\config.yaml loaded successfully]
[2024-02-24 22:53:43,995:INFO:common:yaml file: config\config.yaml loaded successfully]
[2024-02-24 23:09:42,450:INFO:common:yaml file: config\config.yaml loaded successfully]
[2024-02-24 23:09:42,450:INFO:common:yaml file: params.yaml loaded successfully]
[2024-02-24 23:11:13,908:INFO:common:yaml file: config\config.yaml loaded successfully]
[2024-02-24 23:11:13,912:INFO:common:yaml file: params.yaml loaded successfully]
[2024-02-24 23:11:13,913:INFO:common:created directory at: artifacts]
[2024-02-24 23:11:13,996:INFO:common:created directory at: artifacts/data_ingestion]
[2024-02-24 23:12:33,725:INFO:common:yaml file: config\config.yaml loaded successfully]
[2024-02-24 23:12:33,727:INFO:common:yaml file: params.yaml loaded successfully]
[2024-02-24 23:12:33,728:INFO:common:created directory at: artifacts]
[2024-02-24 23:12:33,729:INFO:common:created directory at: artifacts/data_ingestion]
[2024-02-24 23:13:02,336:INFO:common:yaml file: config\config.yaml loaded successfully]
[2024-02-24 23:13:02,337:INFO:common:yaml file: params.yaml loaded successfully]
[2024-02-24 23:13:02,339:INFO:common:created directory at: artifacts]
[2024-02-24 23:13:02,339:INFO:common:created directory at: artifacts/data_ingestion]
[2024-02-24 23:13:02,341:ERROR:472521281:An error occurred while downloading the dataset: name 'KaggleAPi' is not defined]
Traceback (most recent call last):
  File "C:\Users\Khandoker\AppData\Local\Temp\ipykernel_28060\472521281.py", line 13, in download_file
    api=KaggleAPi()
NameError: name 'KaggleAPi' is not defined. Did you mean: 'KaggleApi'?
[2024-02-24 23:16:26,286:INFO:common:yaml file: config\config.yaml loaded successfully]
[2024-02-24 23:16:26,287:INFO:common:yaml file: params.yaml loaded successfully]
[2024-02-24 23:16:26,289:INFO:common:created directory at: artifacts]
[2024-02-24 23:16:26,291:INFO:common:created directory at: artifacts/data_ingestion]
[2024-02-24 23:16:26,299:ERROR:3777164371:An error occurred while downloading the dataset: not enough values to unpack (expected 3, got 2)]
Traceback (most recent call last):
  File "C:\Users\Khandoker\AppData\Local\Temp\ipykernel_28060\3777164371.py", line 16, in download_file
    api.dataset_download_files(
  File "F:\projects\end-to-end-mlops-chicken-diseases-classification-project\end-to-end-mlops-chicken-diseases-classification-project\chicken\lib\site-packages\kaggle\api\kaggle_api_extended.py", line 1430, in dataset_download_files
    owner_slug, dataset_slug, dataset_version_number = self.split_dataset_string(
ValueError: not enough values to unpack (expected 3, got 2)
[2024-02-24 23:19:22,622:INFO:common:yaml file: config\config.yaml loaded successfully]
[2024-02-24 23:19:22,629:INFO:common:yaml file: params.yaml loaded successfully]
[2024-02-24 23:19:22,629:INFO:common:created directory at: artifacts]
[2024-02-24 23:19:22,629:INFO:common:created directory at: artifacts/data_ingestion]
[2024-02-25 00:10:17,601:INFO:common:yaml file: config\config.yaml loaded successfully]
[2024-02-25 00:10:17,713:INFO:common:yaml file: params.yaml loaded successfully]
[2024-02-25 00:10:51,540:INFO:common:yaml file: config\config.yaml loaded successfully]
[2024-02-25 00:10:51,546:INFO:common:yaml file: params.yaml loaded successfully]
[2024-02-25 00:10:51,548:INFO:common:created directory at: artifacts]
[2024-02-25 00:10:51,550:INFO:common:created directory at: artifacts/data_ingestion]
[2024-02-25 00:11:32,519:INFO:common:yaml file: config\config.yaml loaded successfully]
[2024-02-25 00:11:32,523:INFO:common:yaml file: params.yaml loaded successfully]
[2024-02-25 00:11:32,526:INFO:common:created directory at: artifacts]
[2024-02-25 00:11:32,526:INFO:common:created directory at: artifacts/data_ingestion]
[2024-02-25 00:12:22,475:INFO:common:yaml file: config\config.yaml loaded successfully]
[2024-02-25 00:12:22,477:INFO:common:yaml file: params.yaml loaded successfully]
[2024-02-25 00:12:22,478:INFO:common:created directory at: artifacts]
[2024-02-25 00:12:22,480:INFO:common:created directory at: artifacts/data_ingestion]
[2024-02-25 00:12:22,480:ERROR:4028688831:An error occurred while downloading the dataset: name 'KaggleAPi' is not defined]
Traceback (most recent call last):
  File "C:\Users\Khandoker\AppData\Local\Temp\ipykernel_33828\4028688831.py", line 13, in download_file
    api=KaggleAPi()
NameError: name 'KaggleAPi' is not defined. Did you mean: 'KaggleApi'?
[2024-02-25 00:12:41,573:INFO:common:yaml file: config\config.yaml loaded successfully]
[2024-02-25 00:12:41,575:INFO:common:yaml file: params.yaml loaded successfully]
[2024-02-25 00:12:41,576:INFO:common:created directory at: artifacts]
[2024-02-25 00:12:41,577:INFO:common:created directory at: artifacts/data_ingestion]
[2024-02-25 00:21:54,959:INFO:2134624008:Dataset downloaded to artifacts/data_ingestion]
[2024-02-25 00:47:44,319:INFO:main:welcome to my custom log]
[2024-02-25 00:48:20,607:INFO:main:>>>>>> stage Data Ingestion Stage started <<<<<<]
[2024-02-25 00:48:20,609:INFO:common:yaml file: config\config.yaml loaded successfully]
[2024-02-25 00:48:20,611:INFO:common:yaml file: params.yaml loaded successfully]
[2024-02-25 00:48:20,611:INFO:common:created directory at: artifacts]
[2024-02-25 00:48:20,612:INFO:common:created directory at: artifacts/data_ingestion]
[2024-02-25 00:50:40,153:ERROR:data_ingestion:An error occurred while downloading the dataset: ('Connection broken: IncompleteRead(691113274 bytes read, 1503543293 more expected)', IncompleteRead(691113274 bytes read, 1503543293 more expected))]
Traceback (most recent call last):
  File "F:\projects\end-to-end-mlops-chicken-diseases-classification-project\end-to-end-mlops-chicken-diseases-classification-project\chicken\lib\site-packages\urllib3\response.py", line 710, in _error_catcher
    yield
  File "F:\projects\end-to-end-mlops-chicken-diseases-classification-project\end-to-end-mlops-chicken-diseases-classification-project\chicken\lib\site-packages\urllib3\response.py", line 835, in _raw_read
    raise IncompleteRead(self._fp_bytes_read, self.length_remaining)
urllib3.exceptions.IncompleteRead: IncompleteRead(691113274 bytes read, 1503543293 more expected)

The above exception was the direct cause of the following exception:

Traceback (most recent call last):
  File "f:\projects\end-to-end-mlops-chicken-diseases-classification-project\end-to-end-mlops-chicken-diseases-classification-project\src\cnnClassifier\components\data_ingestion.py", line 23, in download_file
    api.dataset_download_files(
  File "F:\projects\end-to-end-mlops-chicken-diseases-classification-project\end-to-end-mlops-chicken-diseases-classification-project\chicken\lib\site-packages\kaggle\api\kaggle_api_extended.py", line 1447, in dataset_download_files
    self.download_file(response, outfile, quiet, not force)
  File "F:\projects\end-to-end-mlops-chicken-diseases-classification-project\end-to-end-mlops-chicken-diseases-classification-project\chicken\lib\site-packages\kaggle\api\kaggle_api_extended.py", line 1874, in download_file
    data = response.read(chunk_size)
  File "F:\projects\end-to-end-mlops-chicken-diseases-classification-project\end-to-end-mlops-chicken-diseases-classification-project\chicken\lib\site-packages\urllib3\response.py", line 907, in read
    data = self._raw_read(amt)
  File "F:\projects\end-to-end-mlops-chicken-diseases-classification-project\end-to-end-mlops-chicken-diseases-classification-project\chicken\lib\site-packages\urllib3\response.py", line 813, in _raw_read
    with self._error_catcher():
  File "F:\projects\end-to-end-mlops-chicken-diseases-classification-project\end-to-end-mlops-chicken-diseases-classification-project\chicken\lib\contextlib.py", line 153, in __exit__
    self.gen.throw(typ, value, traceback)
  File "F:\projects\end-to-end-mlops-chicken-diseases-classification-project\end-to-end-mlops-chicken-diseases-classification-project\chicken\lib\site-packages\urllib3\response.py", line 727, in _error_catcher
    raise ProtocolError(f"Connection broken: {e!r}", e) from e
urllib3.exceptions.ProtocolError: ('Connection broken: IncompleteRead(691113274 bytes read, 1503543293 more expected)', IncompleteRead(691113274 bytes read, 1503543293 more expected))
[2024-02-25 00:50:40,172:INFO:main:>>>>>> stage Data Ingestion Stage completed <<<<<<

x==========x]
[2024-02-25 01:08:31,861:INFO:main:>>>>>> stage Data Ingestion Stage started <<<<<<]
[2024-02-25 01:08:31,862:INFO:common:yaml file: config\config.yaml loaded successfully]
[2024-02-25 01:08:31,863:INFO:common:yaml file: params.yaml loaded successfully]
[2024-02-25 01:08:31,864:INFO:common:created directory at: artifacts]
[2024-02-25 01:08:31,864:INFO:common:created directory at: artifacts/data_ingestion]
[2024-02-25 01:17:28,073:INFO:data_ingestion:Dataset downloaded to artifacts/data_ingestion]
[2024-02-25 01:17:28,078:ERROR:main:[Errno 2] No such file or directory: 'artifacts/data_ingestion/eurosat-dataset.zip']
Traceback (most recent call last):
  File "F:\projects\end-to-end-mlops-chicken-diseases-classification-project\end-to-end-mlops-chicken-diseases-classification-project\main.py", line 9, in <module>
    data_ingestion.main()
  File "f:\projects\end-to-end-mlops-chicken-diseases-classification-project\end-to-end-mlops-chicken-diseases-classification-project\src\cnnClassifier\pipeline\stage_01_data_ingestion.py", line 17, in main
    data_ingestion.extract_zip_file()
  File "f:\projects\end-to-end-mlops-chicken-diseases-classification-project\end-to-end-mlops-chicken-diseases-classification-project\src\cnnClassifier\components\data_ingestion.py", line 39, in extract_zip_file
    with zipfile.ZipFile(self.config.local_data_file, 'r') as zip_ref:
  File "F:\projects\end-to-end-mlops-chicken-diseases-classification-project\end-to-end-mlops-chicken-diseases-classification-project\chicken\lib\zipfile.py", line 1251, in __init__
    self.fp = io.open(file, filemode)
FileNotFoundError: [Errno 2] No such file or directory: 'artifacts/data_ingestion/eurosat-dataset.zip'
